{
  "version": 8,
  "blockIdVersion": 10,
  "anchorX": 0,
  "anchorY": 0,
  "anchorZ": 0,
  "blocks": [
    {
      "x": -3,
      "y": 0,
      "z": -3,
      "name": "Rock_Shale_Brick_Ornate"
    },
    {
      "x": -3,
      "y": 0,
      "z": -2,
      "name": "Rock_Shale_Brick_Ornate"
    },
    {
      "x": -3,
      "y": 0,
      "z": -1,
      "name": "Rock_Shale_Brick_Ornate"
    },
    {
      "x": -3,
      "y": 0,
      "z": 0,
      "name": "Rock_Shale_Brick_Ornate"
    },
    {
      "x": -3,
      "y": 0,
      "z": 1,
      "name": "Rock_Shale_Brick_Ornate"
    },
    {
      "x": -3,
      "y": 0,
      "z": 2,
      "name": "Rock_Shale_Brick_Ornate"
    },
    {
      "x": -3,
      "y": 0,
      "z": 3,
      "name": "Rock_Shale_Brick_Ornate"
    },
    {
      "x": -2,
      "y": 0,
      "z": -3,
      "name": "Rock_Shale_Brick_Ornate"
    },
    {
      "x": -2,
      "y": 0,
      "z": -2,
      "name": "Rock_Shale_Brick_Ornate"
    },
    {
      "x": -2,
      "y": 0,
      "z": -1,
      "name": "Rock_Shale_Brick_Ornate"
    },
    {
      "x": -2,
      "y": 0,
      "z": 0,
      "name": "Rock_Shale_Brick_Ornate"
    },
    {
      "x": -2,
      "y": 0,
      "z": 1,
      "name": "Rock_Shale_Brick_Ornate"
    },
    {
      "x": -2,
      "y": 0,
      "z": 2,
      "name": "Rock_Shale_Brick_Ornate"
    },
    {
      "x": -2,
      "y": 0,
      "z": 3,
      "name": "Rock_Shale_Brick_Ornate"
    },
    {
      "x": -1,
      "y": 0,
      "z": -3,
      "name": "Rock_Shale_Brick_Ornate"
    },
    {
      "x": -1,
      "y": 0,
      "z": -2,
      "name": "Rock_Shale_Brick_Ornate"
    },
    {
      "x": -1,
      "y": 0,
      "z": -1,
      "name": "Rock_Shale_Brick_Ornate"
    },
    {
      "x": -1,
      "y": 0,
      "z": 0,
      "name": "Rock_Shale_Brick_Ornate"
    },
    {
      "x": -1,
      "y": 0,
      "z": 1,
      "name": "Rock_Shale_Brick_Ornate"
    },
    {
      "x": -1,
      "y": 0,
      "z": 2,
      "name": "Rock_Shale_Brick_Ornate"
    },
    {
      "x": -1,
      "y": 0,
      "z": 3,
      "name": "Rock_Shale_Brick_Ornate"
    },
    {
      "x": 0,
      "y": 0,
      "z": -3,
      "name": "Rock_Shale_Brick_Ornate"
    },
    {
      "x": 0,
      "y": 0,
      "z": -2,
      "name": "Rock_Shale_Brick_Ornate"
    },
    {
      "x": 0,
      "y": 0,
      "z": -1,
      "name": "Rock_Shale_Brick_Ornate"
    },
    {
      "x": 0,
      "y": 0,
      "z": 0,
      "name": "Rock_Shale_Brick_Ornate"
    },
    {
      "x": 0,
      "y": 0,
      "z": 1,
      "name": "Rock_Shale_Brick_Ornate"
    },
    {
      "x": 0,
      "y": 0,
      "z": 2,
      "name": "Rock_Shale_Brick_Ornate"
    },
    {
      "x": 0,
      "y": 0,
      "z": 3,
      "name": "Rock_Shale_Brick_Ornate"
    },
    {
      "x": 1,
      "y": 0,
      "z": -3,
      "name": "Rock_Shale_Brick_Ornate"
    },
    {
      "x": 1,
      "y": 0,
      "z": -2,
      "name": "Rock_Shale_Brick_Ornate"
    },
    {
      "x": 1,
      "y": 0,
      "z": -1,
      "name": "Rock_Shale_Brick_Ornate"
    },
    {
      "x": 1,
      "y": 0,
      "z": 0,
      "name": "Rock_Shale_Brick_Ornate"
    },
    {
      "x": 1,
      "y": 0,
      "z": 1,
      "name": "Rock_Shale_Brick_Ornate"
    },
    {
      "x": 1,
      "y": 0,
      "z": 2,
      "name": "Rock_Shale_Brick_Ornate"
    },
    {
      "x": 1,
      "y": 0,
      "z": 3,
      "name": "Rock_Shale_Brick_Ornate"
    },
    {
      "x": 2,
      "y": 0,
      "z": -3,
      "name": "Rock_Shale_Brick_Ornate"
    },
    {
      "x": 2,
      "y": 0,
      "z": -2,
      "name": "Rock_Shale_Brick_Ornate"
    },
    {
      "x": 2,
      "y": 1,
      "z": -2,
      "name": "Rock_Shale_Brick_Stairs",
      "rotation": 3
    },
    {
      "x": 2,
      "y": 2,
      "z": -2,
      "name": "Rock_Shale_Brick_Smooth_Half",
      "rotation": 7
    },
    {
      "x": 2,
      "y": 0,
      "z": -1,
      "name": "Rock_Shale_Brick_Ornate"
    },
    {
      "x": 2,
      "y": 1,
      "z": -1,
      "name": "Rock_Shale_Brick_Ornate"
    },
    {
      "x": 2,
      "y": 2,
      "z": -1,
      "name": "Rock_Shale_Brick_Stairs",
      "rotation": 3
    },
    {
      "x": 2,
      "y": 3,
      "z": -1,
      "name": "Rock_Shale_Brick_Smooth_Half",
      "rotation": 7
    },
    {
      "x": 2,
      "y": 0,
      "z": 0,
      "name": "Rock_Shale_Brick_Ornate"
    },
    {
      "x": 2,
      "y": 1,
      "z": 0,
      "name": "Rock_Shale_Brick_Stairs",
      "rotation": 3
    },
    {
      "x": 2,
      "y": 2,
      "z": 0,
      "name": "Rock_Shale_Brick_Smooth_Half",
      "rotation": 7
    },
    {
      "x": 2,
      "y": 0,
      "z": 1,
      "name": "Rock_Shale_Brick_Ornate"
    },
    {
      "x": 2,
      "y": 1,
      "z": 1,
      "name": "Rock_Shale_Brick_Ornate"
    },
    {
      "x": 2,
      "y": 2,
      "z": 1,
      "name": "Rock_Shale_Brick_Stairs",
      "rotation": 3
    },
    {
      "x": 2,
      "y": 3,
      "z": 1,
      "name": "Rock_Shale_Brick_Smooth_Half",
      "rotation": 7
    },
    {
      "x": 2,
      "y": 0,
      "z": 2,
      "name": "Rock_Shale_Brick_Ornate"
    },
    {
      "x": 2,
      "y": 1,
      "z": 2,
      "name": "Rock_Shale_Brick_Stairs",
      "rotation": 3
    },
    {
      "x": 2,
      "y": 2,
      "z": 2,
      "name": "Rock_Shale_Brick_Smooth_Half",
      "rotation": 7
    },
    {
      "x": 2,
      "y": 0,
      "z": 3,
      "name": "Rock_Shale_Brick_Ornate"
    },
    {
      "x": 3,
      "y": 0,
      "z": -3,
      "name": "Rock_Shale_Brick"
    },
    {
      "x": 3,
      "y": 1,
      "z": -3,
      "name": "Rock_Shale_Brick"
    },
    {
      "x": 3,
      "y": 2,
      "z": -3,
      "name": "Rock_Shale_Brick"
    },
    {
      "x": 3,
      "y": 3,
      "z": -3,
      "name": "Rock_Shale_Brick"
    },
    {
      "x": 3,
      "y": 0,
      "z": -2,
      "name": "Rock_Shale_Brick_Smooth_Half",
      "rotation": 5
    },
    {
      "x": 3,
      "y": 1,
      "z": -2,
      "name": "Rock_Shale_Brick_Smooth_Half",
      "rotation": 5
    },
    {
      "x": 3,
      "y": 2,
      "z": -2,
      "name": "Rock_Shale_Brick_Smooth_Half",
      "rotation": 5
    },
    {
      "x": 3,
      "y": 3,
      "z": -2,
      "name": "Rock_Shale_Brick_Smooth_Half"
    },
    {
      "x": 3,
      "y": 0,
      "z": -1,
      "name": "Rock_Shale_Brick_Decorative"
    },
    {
      "x": 3,
      "y": 1,
      "z": -1,
      "name": "Rock_Shale_Brick_Decorative"
    },
    {
      "x": 3,
      "y": 2,
      "z": -1,
      "name": "Rock_Shale_Brick_Decorative"
    },
    {
      "x": 3,
      "y": 3,
      "z": -1,
      "name": "Rock_Shale_Brick_Smooth_Half"
    },
    {
      "x": 3,
      "y": 0,
      "z": 0,
      "name": "Rock_Shale_Brick_Smooth_Half",
      "rotation": 5
    },
    {
      "x": 3,
      "y": 1,
      "z": 0,
      "name": "Rock_Shale_Brick_Smooth_Half",
      "rotation": 5
    },
    {
      "x": 3,
      "y": 2,
      "z": 0,
      "name": "Rock_Shale_Brick_Smooth_Half",
      "rotation": 5
    },
    {
      "x": 3,
      "y": 3,
      "z": 0,
      "name": "Rock_Shale_Brick_Smooth_Half"
    },
    {
      "x": 3,
      "y": 0,
      "z": 1,
      "name": "Rock_Shale_Brick_Decorative"
    },
    {
      "x": 3,
      "y": 1,
      "z": 1,
      "name": "Rock_Shale_Brick_Decorative"
    },
    {
      "x": 3,
      "y": 2,
      "z": 1,
      "name": "Rock_Shale_Brick_Decorative"
    },
    {
      "x": 3,
      "y": 3,
      "z": 1,
      "name": "Rock_Shale_Brick_Smooth_Half"
    },
    {
      "x": 3,
      "y": 0,
      "z": 2,
      "name": "Rock_Shale_Brick_Smooth_Half",
      "rotation": 5
    },
    {
      "x": 3,
      "y": 1,
      "z": 2,
      "name": "Rock_Shale_Brick_Smooth_Half",
      "rotation": 5
    },
    {
      "x": 3,
      "y": 2,
      "z": 2,
      "name": "Rock_Shale_Brick_Smooth_Half",
      "rotation": 5
    },
    {
      "x": 3,
      "y": 3,
      "z": 2,
      "name": "Rock_Shale_Brick_Smooth_Half"
    },
    {
      "x": 3,
      "y": 0,
      "z": 3,
      "name": "Rock_Shale_Brick"
    },
    {
      "x": 3,
      "y": 1,
      "z": 3,
      "name": "Rock_Shale_Brick"
    },
    {
      "x": 3,
      "y": 2,
      "z": 3,
      "name": "Rock_Shale_Brick"
    },
    {
      "x": 3,
      "y": 3,
      "z": 3,
      "name": "Rock_Shale_Brick"
    }
  ],
  "fluids": [
    {
      "x": -3,
      "y": 0,
      "z": -3,
      "name": "Empty",
      "level": 0
    },
    {
      "x": -3,
      "y": 0,
      "z": -2,
      "name": "Empty",
      "level": 0
    },
    {
      "x": -3,
      "y": 0,
      "z": -1,
      "name": "Empty",
      "level": 0
    },
    {
      "x": -3,
      "y": 0,
      "z": 0,
      "name": "Empty",
      "level": 0
    },
    {
      "x": -3,
      "y": 0,
      "z": 1,
      "name": "Empty",
      "level": 0
    },
    {
      "x": -3,
      "y": 0,
      "z": 2,
      "name": "Empty",
      "level": 0
    },
    {
      "x": -3,
      "y": 0,
      "z": 3,
      "name": "Empty",
      "level": 0
    },
    {
      "x": -2,
      "y": 0,
      "z": -3,
      "name": "Empty",
      "level": 0
    },
    {
      "x": -2,
      "y": 0,
      "z": -2,
      "name": "Empty",
      "level": 0
    },
    {
      "x": -2,
      "y": 0,
      "z": -1,
      "name": "Empty",
      "level": 0
    },
    {
      "x": -2,
      "y": 0,
      "z": 0,
      "name": "Empty",
      "level": 0
    },
    {
      "x": -2,
      "y": 0,
      "z": 1,
      "name": "Empty",
      "level": 0
    },
    {
      "x": -2,
      "y": 0,
      "z": 2,
      "name": "Empty",
      "level": 0
    },
    {
      "x": -2,
      "y": 0,
      "z": 3,
      "name": "Empty",
      "level": 0
    },
    {
      "x": -1,
      "y": 0,
      "z": -3,
      "name": "Empty",
      "level": 0
    },
    {
      "x": -1,
      "y": 0,
      "z": -2,
      "name": "Empty",
      "level": 0
    },
    {
      "x": -1,
      "y": 0,
      "z": -1,
      "name": "Empty",
      "level": 0
    },
    {
      "x": -1,
      "y": 0,
      "z": 0,
      "name": "Empty",
      "level": 0
    },
    {
      "x": -1,
      "y": 0,
      "z": 1,
      "name": "Empty",
      "level": 0
    },
    {
      "x": -1,
      "y": 0,
      "z": 2,
      "name": "Empty",
      "level": 0
    },
    {
      "x": -1,
      "y": 0,
      "z": 3,
      "name": "Empty",
      "level": 0
    },
    {
      "x": 0,
      "y": 0,
      "z": -3,
      "name": "Empty",
      "level": 0
    },
    {
      "x": 0,
      "y": 0,
      "z": -2,
      "name": "Empty",
      "level": 0
    },
    {
      "x": 0,
      "y": 0,
      "z": -1,
      "name": "Empty",
      "level": 0
    },
    {
      "x": 0,
      "y": 0,
      "z": 0,
      "name": "Empty",
      "level": 0
    },
    {
      "x": 0,
      "y": 0,
      "z": 1,
      "name": "Empty",
      "level": 0
    },
    {
      "x": 0,
      "y": 0,
      "z": 2,
      "name": "Empty",
      "level": 0
    },
    {
      "x": 0,
      "y": 0,
      "z": 3,
      "name": "Empty",
      "level": 0
    },
    {
      "x": 1,
      "y": 0,
      "z": -3,
      "name": "Empty",
      "level": 0
    },
    {
      "x": 1,
      "y": 0,
      "z": -2,
      "name": "Empty",
      "level": 0
    },
    {
      "x": 1,
      "y": 0,
      "z": -1,
      "name": "Empty",
      "level": 0
    },
    {
      "x": 1,
      "y": 0,
      "z": 0,
      "name": "Empty",
      "level": 0
    },
    {
      "x": 1,
      "y": 0,
      "z": 1,
      "name": "Empty",
      "level": 0
    },
    {
      "x": 1,
      "y": 0,
      "z": 2,
      "name": "Empty",
      "level": 0
    },
    {
      "x": 1,
      "y": 0,
      "z": 3,
      "name": "Empty",
      "level": 0
    },
    {
      "x": 2,
      "y": 0,
      "z": -3,
      "name": "Empty",
      "level": 0
    },
    {
      "x": 2,
      "y": 0,
      "z": -2,
      "name": "Empty",
      "level": 0
    },
    {
      "x": 2,
      "y": 1,
      "z": -2,
      "name": "Empty",
      "level": 0
    },
    {
      "x": 2,
      "y": 2,
      "z": -2,
      "name": "Empty",
      "level": 0
    },
    {
      "x": 2,
      "y": 0,
      "z": -1,
      "name": "Empty",
      "level": 0
    },
    {
      "x": 2,
      "y": 1,
      "z": -1,
      "name": "Empty",
      "level": 0
    },
    {
      "x": 2,
      "y": 2,
      "z": -1,
      "name": "Empty",
      "level": 0
    },
    {
      "x": 2,
      "y": 3,
      "z": -1,
      "name": "Empty",
      "level": 0
    },
    {
      "x": 2,
      "y": 0,
      "z": 0,
      "name": "Empty",
      "level": 0
    },
    {
      "x": 2,
      "y": 1,
      "z": 0,
      "name": "Empty",
      "level": 0
    },
    {
      "x": 2,
      "y": 2,
      "z": 0,
      "name": "Empty",
      "level": 0
    },
    {
      "x": 2,
      "y": 0,
      "z": 1,
      "name": "Empty",
      "level": 0
    },
    {
      "x": 2,
      "y": 1,
      "z": 1,
      "name": "Empty",
      "level": 0
    },
    {
      "x": 2,
      "y": 2,
      "z": 1,
      "name": "Empty",
      "level": 0
    },
    {
      "x": 2,
      "y": 3,
      "z": 1,
      "name": "Empty",
      "level": 0
    },
    {
      "x": 2,
      "y": 0,
      "z": 2,
      "name": "Empty",
      "level": 0
    },
    {
      "x": 2,
      "y": 1,
      "z": 2,
      "name": "Empty",
      "level": 0
    },
    {
      "x": 2,
      "y": 2,
      "z": 2,
      "name": "Empty",
      "level": 0
    },
    {
      "x": 2,
      "y": 0,
      "z": 3,
      "name": "Empty",
      "level": 0
    },
    {
      "x": 3,
      "y": 0,
      "z": -3,
      "name": "Empty",
      "level": 0
    },
    {
      "x": 3,
      "y": 1,
      "z": -3,
      "name": "Empty",
      "level": 0
    },
    {
      "x": 3,
      "y": 2,
      "z": -3,
      "name": "Empty",
      "level": 0
    },
    {
      "x": 3,
      "y": 3,
      "z": -3,
      "name": "Empty",
      "level": 0
    },
    {
      "x": 3,
      "y": 0,
      "z": -2,
      "name": "Empty",
      "level": 0
    },
    {
      "x": 3,
      "y": 1,
      "z": -2,
      "name": "Empty",
      "level": 0
    },
    {
      "x": 3,
      "y": 2,
      "z": -2,
      "name": "Empty",
      "level": 0
    },
    {
      "x": 3,
      "y": 3,
      "z": -2,
      "name": "Empty",
      "level": 0
    },
    {
      "x": 3,
      "y": 0,
      "z": -1,
      "name": "Empty",
      "level": 0
    },
    {
      "x": 3,
      "y": 1,
      "z": -1,
      "name": "Empty",
      "level": 0
    },
    {
      "x": 3,
      "y": 2,
      "z": -1,
      "name": "Empty",
      "level": 0
    },
    {
      "x": 3,
      "y": 3,
      "z": -1,
      "name": "Empty",
      "level": 0
    },
    {
      "x": 3,
      "y": 0,
      "z": 0,
      "name": "Empty",
      "level": 0
    },
    {
      "x": 3,
      "y": 1,
      "z": 0,
      "name": "Empty",
      "level": 0
    },
    {
      "x": 3,
      "y": 2,
      "z": 0,
      "name": "Empty",
      "level": 0
    },
    {
      "x": 3,
      "y": 3,
      "z": 0,
      "name": "Empty",
      "level": 0
    },
    {
      "x": 3,
      "y": 0,
      "z": 1,
      "name": "Empty",
      "level": 0
    },
    {
      "x": 3,
      "y": 1,
      "z": 1,
      "name": "Empty",
      "level": 0
    },
    {
      "x": 3,
      "y": 2,
      "z": 1,
      "name": "Empty",
      "level": 0
    },
    {
      "x": 3,
      "y": 3,
      "z": 1,
      "name": "Empty",
      "level": 0
    },
    {
      "x": 3,
      "y": 0,
      "z": 2,
      "name": "Empty",
      "level": 0
    },
    {
      "x": 3,
      "y": 1,
      "z": 2,
      "name": "Empty",
      "level": 0
    },
    {
      "x": 3,
      "y": 2,
      "z": 2,
      "name": "Empty",
      "level": 0
    },
    {
      "x": 3,
      "y": 3,
      "z": 2,
      "name": "Empty",
      "level": 0
    },
    {
      "x": 3,
      "y": 0,
      "z": 3,
      "name": "Empty",
      "level": 0
    },
    {
      "x": 3,
      "y": 1,
      "z": 3,
      "name": "Empty",
      "level": 0
    },
    {
      "x": 3,
      "y": 2,
      "z": 3,
      "name": "Empty",
      "level": 0
    },
    {
      "x": 3,
      "y": 3,
      "z": 3,
      "name": "Empty",
      "level": 0
    }
  ]
}